<?xml version="1.0"?>
<robot name="wchair">
<!-- Rosso:= Asse x		 Verde:= Asse y	 Blue := Asse z -->
<!-- ##################################################################### -->
<!--_____________________BASE LINK_________________________________________-->
	<link name="base_link">
		<visual>
			<origin xyz="0 0 0" rpy="0 0 0" />
			<geometry><box size="0.75 0.5 0.30"/></geometry>
			<material name="blue"><color rgba="0 0.5 1 1"/></material>
		</visual>
		<!-- Base collision -->
		<collision>
			<origin xyz="0 0 0" rpy="0 0 0" />
			<geometry><box size="0.75 0.5 0.30"/></geometry>
		</collision>
		<inertial>
			<mass value="5"/>
			<inertia ixx="0.13" ixy="0.0" ixz="0.0" iyy="0.21" iyz="0.0" izz="0.13"/>
		</inertial>
	</link>
	<gazebo reference="base_link">
		<material>Gazebo/SkyBlue</material>
		<!-- <turnGravityOff>false</turnGravityOff> -->
	</gazebo>
<!-- ##################################################################### -->
	<!-- Caster -->
	<link name="caster_link">
		<visual>
			<origin xyz="0 0 0" rpy="0 0 0" />
			<geometry><sphere radius="0.1" /></geometry>
			<material name="White"/>
		</visual>
		<!-- Caster collision -->
		<collision>
			<origin xyz="0 0 0" rpy="0 0 0" />
			<geometry><sphere radius="0.1" /></geometry>
		</collision>
		<inertial>
			<mass value="0.5"/>
			<inertia ixx="0.0001" ixy="0.0" ixz="0.0" iyy="0.0001" iyz="0.0" izz="0.0001"/>
		</inertial>
	</link>
	<joint name="caster_joint" type="continuous">
    	<parent link="base_link"/>
    	<child link="caster_link"/>
    	<origin xyz="0.25 0 -0.15" rpy="0 0 0" />
    	<axis xyz="0 0 1" />
  	</joint>
  	<gazebo reference="caster_link">
  		<material>Gazebo/Grey</material>
    	<!-- <turnGravityOff>false</turnGravityOff> -->
  	</gazebo>
<!-- ##################################################################### -->
	<!-- Right Wheel -->
	<link name="right_wheel">
		<visual>
			<origin xyz="0 0 0" rpy="1.570795 0 0" />
			<geometry><cylinder length="0.1" radius="0.2" /></geometry>
			<material name="white"><color rgba="255 255 255 1"/></material>
		</visual>
			<!-- Right Wheel collision -->
			<collision>
				<origin xyz="0 0 0" rpy="1.570795 0 0" />
				<geometry><cylinder length="0.1" radius="0.2" /></geometry>
			</collision>
		<inertial>
			<mass value="5"/>
			<inertia ixx="0.01" ixy="0.0" ixz="0.0" iyy="0.005" iyz="0.0" izz="0.005"/>
		</inertial>
	</link>
	<joint name="right_wheel_joint" type="revolute">
		<parent link="base_link"/>
		<child link="right_wheel"/>
		<origin xyz="-0.15 -0.3 -0.05" rpy="0 0 0" />
		<axis xyz="0 1 0" />
	</joint>
	<!-- Transmission is important to link the joints and the controller -->
	<transmission name="right_wheel_joint_trans">
		<type>transmission_interface/SimpleTransmission</type>
		<joint name="right_wheel_joint"/>
		<actuator name="right_wheel_joint_motor">
			<hardwareInterface>EffortJointInterface</hardwareInterface>
			<mechanicalReduction>1</mechanicalReduction>
		</actuator>
	</transmission>
	<gazebo reference="right_wheel">
		<material>Gazebo/Grey</material>
		<!-- <turnGravityOff>false</turnGravityOff> -->
		<mu1 value="1.0"/>
		<mu2 value="1.0"/>
		<kp value="10000000.0"/>
		<kd value="1.0"/>
	</gazebo>
<!-- ################################################################## -->	
	<!-- Left Wheel -->
	<link name="left_wheel">
		<visual>
			<origin xyz="0 0 0" rpy="1.570795 0 0" />
			<geometry><cylinder length="0.1" radius="0.2" /></geometry>
			<material name="white"/><color rgba="255 255 255 1"/></material>
		</visual>
		<!-- Left Wheel collision -->
		<collision>
			<origin xyz="0 0 0" rpy="1.570795 0 0" />
			<geometry><cylinder length="0.1" radius="0.2" /></geometry>
		</collision>
		<inertial>
			<mass value="0.5"/>
			<inertia ixx="0.01" ixy="0.0" ixz="0.0" iyy="0.005" iyz="0.0" izz="0.005"/>
		</inertial>
	</link>
	<joint name="joint_left_wheel" type="revolute">
		<parent link="base_link"/>
		<child link="left_wheel"/>
		<origin xyz="-0.15 0.3 -0.05" rpy="0 0 0" />
		<axis xyz="0 1 0" />
	</joint>
	<!-- Transmission is important to link the joints and the controller -->
	<transmission name="left_wheel_joint_trans">
		<type>transmission_interface/SimpleTransmission</type>
		<joint name="left_wheel_joint"/>
		<actuator name="left_wheel_joint_motor">
			<hardwareInterface>EffortJointInterface</hardwareInterface>
			<mechanicalReduction>1</mechanicalReduction>
		</actuator>
	</transmission>
	<gazebo reference="left_wheel">
		<material>Gazebo/Grey</material>
		<!-- <turnGravityOff>false</turnGravityOff> -->
		<mu1 value="1.0"/>
		<mu2 value="1.0"/>
		<kp value="10000000.0"/>
		<kd value="1.0"/>
	</gazebo>
	
<!-- ################################################################## -->	
	<!-- PEDANA 1 -->
	<link name="pedana1">
		<visual>
			<origin xyz="0 0 0" rpy="0 0 0" />
			<geometry><box size="0.02 0.5 0.35" /></geometry>
			<material name="white"/><color rgba="255 255 255 1"/></material>
		</visual>
		<collision>
			<origin xyz="0 0 0" rpy="0 0 0" />
			<geometry><box size="0.02 0.5 0.35" /></geometry>
		</collision>
	</link>
	<joint name="joint_pedana1" type="fixed">
		<parent link="base_link"/>
		<child link="pedana1"/>
		<origin xyz="0.45 0 0.05" rpy="0 -0.2 0" />
	</joint>

<!-- ################################################################## -->	
	<!-- PEDANA 2 -->
	<link name="pedana2">
		<visual>
			<origin xyz="0 0 0" rpy="0 0 0" />
			<geometry><box size="0.25 0.5 0.02" /></geometry>
			<material name="white"/><color rgba="255 255 255 1"/></material>
		</visual>
		<collision>
			<origin xyz="0 0 0" rpy="0 0 0" />
			<geometry><box size="0.25 0.5 0.02" /></geometry>
		</collision>
	</link>
	<joint name="joint_pedana2" type="fixed">
		<parent link="base_link"/>
		<child link="pedana2"/>
		<origin xyz="0.55 0 -0.12" rpy="0 0 0" />
	</joint>
	
<!-- ################################################################## -->	
	<!-- SEDILE -->
	<link name="sedile">
		<visual>
			<origin xyz="0 0 0" rpy="0 0 0" />
			<geometry><box size="0.35 0.5 0.08" /></geometry>
			<material name="white"/><color rgba="255 255 255 1"/></material>
		</visual>
		<collision>
			<origin xyz="0 0 0" rpy="0 0 0" />
			<geometry><box size="0.35 0.5 0.08" /></geometry>
		</collision>
	</link>
	<joint name="joint_sedile" type="fixed">
		<parent link="base_link"/>
		<child link="sedile"/>
		<origin xyz="0.19 0 0.19" rpy="0 0 0" />
	</joint>
<!-- ################################################################## -->	
	<!-- SCHIENALE -->
	<link name="schienale">
		<visual>
			<origin xyz="0 0 0" rpy="0 0 0" />
			<geometry><box size="0.06 0.5 0.48" /></geometry>
			<material name="white"/><color rgba="255 255 255 1"/></material>
		</visual>
		<collision>
			<origin xyz="0 0 0" rpy="0 0 0" />
			<geometry><box size="0.06 0.5 0.48" /></geometry>
		</collision>
	</link>
	<joint name="joint_schienale" type="fixed">
		<parent link="base_link"/>
		<child link="schienale"/>
		<origin xyz="0 0 0.45" rpy="0 -0.2 0" />
	</joint>

<!-- ################################################################## -->	
	<!-- BRACCIOLO DX-->
	<link name="bracciolo_dx">
		<visual>
			<origin xyz="0 0 0" rpy="0 0 0" />
			<geometry><box size="0.40 0.06 0.04" /></geometry>
			<material name="white"/><color rgba="255 255 255 1"/></material>
		</visual>
		<collision>
			<origin xyz="0 0 0" rpy="0 0 0" />
			<geometry><box size="0.40 0.06 0.04" /></geometry>
		</collision>
	</link>
	<joint name="joint_bracciolo_dx" type="fixed">
		<parent link="base_link"/>
		<child link="bracciolo_dx"/>
		<origin xyz="0.16 -0.28 0.4" rpy="0 0 0" />
	</joint>
<!-- ################################################################## -->	
	<!-- BRACCIOLO SX-->
	<link name="bracciolo_sx">
		<visual>
			<origin xyz="0 0 0" rpy="0 0 0" />
			<geometry><box size="0.40 0.06 0.04" /></geometry>
			<material name="white"/><color rgba="255 255 255 1"/></material>
		</visual>
		<collision>
			<origin xyz="0 0 0" rpy="0 0 0" />
			<geometry><box size="0.40 0.06 0.04" /></geometry>
		</collision>
	</link>
	<joint name="joint_bracciolo_sx" type="fixed">
		<parent link="base_link"/>
		<child link="bracciolo_sx"/>
		<origin xyz="0.16 0.28 0.4" rpy="0 0 0" />
	</joint>
	
<!-- ##################################################################### -->
	<!-- SENSORS hokuyo -->
	<link name="hokuyo_link">
		<visual>
			<origin xyz="0 0 0" rpy="0 0 0"/>
			<geometry><box size="0.05 0.05 0.05"/></geometry>
			<material name="Black" />
		</visual>
	</link>
	<joint name="hokuyo_joint" type="fixed">
		<origin xyz="0.7 0 -0.085" rpy="0 0 0" />
		<parent link="base_link"/>
		<child link="hokuyo_link" />
	</joint>
	<gazebo reference="hokuyo_link">
		<material>Gazebo/Black</material>
		<!-- <turnGravityOff>false</turnGravityOff> -->
		<sensor type="ray" name="head_hokuyo_sensor">
			<pose>0.025 0 0 0 0 0</pose>
			<visualize>false</visualize>
			<update_rate>50</update_rate>
			<ray>
				<scan>
					<horizontal>
						<samples>720</samples>
						<resolution>1</resolution>
						<min_angle>-1.570796</min_angle>
						<max_angle>1.570796</max_angle>
					</horizontal>
				</scan>
				<range>
					<min>0.10</min>
					<max>10.0</max>
					<resolution>0.001</resolution>
				</range>
			</ray>
			<plugin name="gazebo_ros_head_hokuyo_controller" filename="libgazebo_ros_laser.so">
				<topicName>/scan</topicName>
				<frameName>hokuyo_link</frameName>
			</plugin>
		</sensor>
	</gazebo>
	
<!-- ##################################################################### -->
	<!-- SENSORS imu -->	
	<link name="imu_link">
  		<visual>
    		<origin rpy="0 0 0" xyz="0 0 0"/>
    		<geometry><box size="0.05 0.05 0.05"/></geometry>
      		<material name="Orange" />
  		</visual>
	</link>
	<joint name="imu_joint" type="fixed">
    	<origin xyz="-0.325 0 0.150" rpy="0 0 0"/>
    	<parent link="base_link"/>
    	<child link="imu_link"/>
  	</joint>
		<gazebo reference="imu_link">
		<material>Gazebo/Orange</material>
		<!-- <turnGravityOff>false</turnGravityOff> -->
		<update_rate>50.0</update_rate>
		<sensor name="imu_sensor" type="imu">
			<pose>0 0 0 0 0 0</pose>
			<plugin name="imu_plugin" filename="libhector_gazebo_ros_imu.so">
    	  		<alwaysOn>true</alwaysOn>
    	  		<bodyName>base_link</bodyName>
    	  		<topicName>/imu</topicName>
    	  		<frameName>imu_link</frameName>
    	  		<gaussianNoise>0.0</gaussianNoise> 
    	  		<serviceName>imu/calibrate</serviceName>
    	  		<rpyOffset>0 0 0</rpyOffset> 
				<accelDrift>0.5 0.5 0.5</accelDrift>
				<accelGaussianNoise>0.35 0.35 0.3</accelGaussianNoise>
				<rateDrift>0.1 0.1 0.1</rateDrift>
				<rateGaussianNoise>0.05 0.05 0.015</rateGaussianNoise>
    		</plugin>
    	</sensor> 
  	</gazebo>	
<!-- ##################################################################### -->	
	<!-- Differential drive controller  -->
	<gazebo>
		<plugin filename="libgazebo_ros_diff_drive.so" name="differential_drive_controller_front">
			<rosDebugLevel>Debug</rosDebugLevel>
			<publishWheelTF>True</publishWheelTF>
			<publishTf>1</publishTf>
			<publishWheelJointState>true</publishWheelJointState>
			<alwaysOn>true</alwaysOn>
			<updateRate>100.0</updateRate>
			<leftJoint>left_wheel_joint</leftJoint>
			<rightJoint>right_wheel_joint</rightJoint>
			<wheelSeparation>0.5</wheelSeparation>
			<wheelDiameter>0.4</wheelDiameter>
			<broadcastTF>1</broadcastTF>
			<wheelTorque>30</wheelTorque>
			<wheelAcceleration>1.8</wheelAcceleration>
			<commandTopic>cmd_vel</commandTopic>
			<odometryFrame>odom</odometryFrame>
			<odometryTopic>odom</odometryTopic>
			<robotBaseFrame>base_link</robotBaseFrame>
		</plugin>
	</gazebo>
</robot>

